Workbook
Name Imprimir_área_IM: #REF!

Sheet Contents
B2: Contents
B3: Historical Statements and Financial Projections
B4: Summary of recent years, projections, and objectives
B6: Hoja | C6: Description
B8: Financial Objectives | C8: Financial Objective
B9: Revenue | C9: Historical and projected revenue
B10: Costs | C10: Historical and projected costs
B11: Expenses | C11: Historical and projected expenses
B12: Personal | C12: Worksheet to calculate personnel expenses by role
B14: Loans | C14: Table to calculate compound interest for an amount, rate, and loan term
B15: Income Statement | C15: Historical and Projected Income Statements
B16: Balance Sheet | C16: Historical and Projected Balance Sheets
B17: Ratios | C17: Financial Ratios for Profitability, Activity, and Leverage
D27: 3

Sheet P&L (Old)
A1: =Costs!A1:I1 -> Company Suquimsa | B1: <<Contenido
A2: INCOME STATEMENT
A3: SUQUIMSA
C5: HISTORICALS | G5: PROJECTEDS | J5: PROJECTEDS | O5: PROJECTED | Q5: DIFERENCIA | S5: PERCENTAGE
E6: Years of Operations | O6: 2006 | Q6: DIFERENCIA | S6: PERCENTAGE
C7: 2004 | D7: 2005 | E7: 2006 | F7: =E7+1 -> 2007 | G7: =F7+1 -> 2008 | H7: =G7+1 -> 2009 | I7: =H7+1 -> 2010 | J7: =I7+1 -> 2011 | K7: =J7+1 -> 2012
P8: =O8+1 -> 1 | R8: =Q8+1 -> 1
B9: SALES | C9: 232109 | D9: =Revenue!#REF! -> #REF! | E9: 666134 | F9: 1018321 | G9: =Revenue!F23 -> 1457273 | H9: =Revenue!G23 -> 1868951.7 | I9: =Revenue!H23 -> 2172293.2 | J9: =Revenue!I23 -> 2499902 | O9: 675438.75 | P9: =E9/D9 -> #REF! | Q9: =E9-O9 -> -9304.75 | R9: =G9/F9 -> 1.4310546 | S9: =E9/O9 -> 0.98622414
B11: COST OF SALES | C11: 76596 | D11: =Costs!D18 -> 0 | E11: 266160 | F11: 445602 | G11: =Costs!G18 -> 749626.34 | H11: =Costs!H18 -> 841899.78 | I11: =Costs!I18 -> 937247.98 | J11: =Costs!#REF! -> #REF! | O11: 184683.6 | Q11: =E11-O11 -> 81476.4 | S11: =E11/O11 -> 1.4411675
G12: =F12
B13: GROSS PROFIT | C13: =C9-C11 -> 155513 | D13: =D9-D11 -> #REF! | E13: =E9-E11 -> 399974 | F13: =F9-F11 -> 572719 | G13: =G9-G11 -> 707646.66 | H13: =H9-H11 -> 1027051.9 | I13: =I9-I11 -> 1235045.2 | J13: =J9-J11 -> #REF! | O13: 490755.15 | Q13: =E13-O13 -> -90781.15 | S13: =E13/O13 -> 0.81501743
B15: ADMINISTRATIVE AND GENERAL EXPENSES | C15: =140895-C26 -> 102920 | D15: =170799-D26 -> 139066.51 | E15: 234168 | F15: =SUM(F16:F21) -> #REF! | G15: =SUM(G16:G22) -> #REF! | H15: =SUM(H16:H22) -> #REF! | I15: =SUM(I16:I22) -> #REF! | J15: =SUM(J16:J22) -> #REF! | O15: 241982.18 | P15: =E15/D15 -> 1.6838562 | Q15: =E15-O15 -> -7814.185 | R15: =G15/F15 -> #REF! | S15: =E15/O15 -> 0.9677076
B16: Personal | D16: 57543 | E16: 78252 | F16: =108373+11627 -> 120000 | G16: =Personal!G27 -> 215841.6 | H16: =G16*1.05 -> 226633.68 | I16: =H16*1.05 -> 237965.36 | J16: =I16*1.05 -> 249863.63 | O16: 140034.96 | Q16: =E16-O16 -> -61782.96 | S16: =E16/O16 -> 0.55880332
B17: Sales commission | D17: 9291 | E17: =E9*0.015 -> 9992.01 | F17: =F9*0.013 -> 13238.173 | G17: =G9*0.013 -> 18944.549 | H17: =H9*0.013 -> 24296.372 | I17: =I9*0.013 -> 28239.811 | J17: =J9*0.013 -> 32498.726 | O17: 16210.53 | Q17: =E17-O17 -> -6218.52 | S17: =E17/O17 -> 0.61639009
B18: Depreciation Equipments (1) | D18: 11275 | E18: 14175 | F18: 17875 | G18: =F18 -> 17875 | H18: =G18 -> 17875 | I18: =H18 -> 17875 | J18: =I18 -> 17875 | O18: 11275 | Q18: =E18-O18 -> 2900 | S18: =E18/O18 -> 1.2572062
B19: Common administrative expenses | D19: =Expenses!#REF! -> #REF! | E19: 114464 | F19: =Expenses!#REF! -> #REF! | G19: =F19*1.12 -> #REF! | H19: =G19*1.12 -> #REF! | I19: =H19*1.12 -> #REF! | J19: =I19*1.12 -> #REF! | O19: 71716.944 | Q19: =E19-O19 -> 42747.056 | S19: =E19/O19 -> 1.5960524
B20: Marketing and advertising expenses (2) | D20: =Expenses!#REF! -> #REF! | E20: =D20*1.15 -> #REF! | F20: =Expenses!#REF! -> #REF! | G20: 50000 | H20: =G20*0.75 -> 37500 | I20: =H20*0.75 -> 28125 | J20: =I20 -> 28125 | O20: 2744.751 | Q20: =E20-O20 -> #REF! | S20: =E20/O20 -> #REF!
B21: Other expenses | D21: 0 | E21: =Expenses!#REF! -> #REF! | F21: =Expenses!B36 -> 678117.82 | G21: =F21*1.1 -> 745929.6 | H21: =G21*1.1 -> 820522.56 | I21: =H21*1.1 -> 902574.82 | J21: =I21*1.1 -> 992832.3 | O21: 0 | Q21: =E21-O21 -> #REF!
B22: Reservas de cuentas malas | G22: =G9*0.015 -> 21859.095 | H22: =H9*0.015 -> 28034.275 | I22: =I9*0.015 -> 32584.398 | J22: =J9*0.015 -> 37498.53
B24: UAII | C24: =C13-C15 -> 52593 | D24: =D13-D15 -> #REF! | E24: =E13-E15 -> 165806 | F24: =F13-F15 -> #REF! | G24: =G13-G15 -> #REF! | H24: =H13-H15 -> #REF! | I24: =I13-I15 -> #REF! | J24: =J13-J15 -> #REF! | O24: 248772.97 | Q24: =E24-O24 -> -82966.965 | S24: =E24/O24 -> 0.66649525
F25: =E25 | G25: =F25
B26: INTEREST | C26: =SUM(C27:C36) -> 37975 | D26: =SUM(D27:D36) -> 31732.49 | E26: =SUM(E27:E36) -> 53629.96 | F26: =SUM(F27:F36) -> #REF! | G26: =SUM(G27:G36) -> #REF! | H26: =SUM(H27:H36) -> #REF! | I26: =SUM(I27:I36) -> #REF! | J26: =SUM(J27:J36) -> #REF! | O26: 19200 | Q26: =E26-O26 -> 34429.96 | S26: =E26/O26 -> 2.7932271
B27: Financia Loan 1 (2005 NO es Financia) | C27: 13375 | D27: 6583 | E27: =+LOANS!E17 -> 52403.4 | F27: =+LOANS!E18 -> 48696.795 | G27: =+LOANS!E19 -> 44712.707 | H27: 0 | I27: 0 | J27: 0 | O27: 4200 | S27: =E27/O27 -> 12.477
B28: Loan Financing 2 | F28: =LOANS!#REF! -> #REF! | G28: =LOANS!#REF! -> #REF! | H28: =LOANS!#REF! -> #REF! | I28: 0 | J28: 0
B29: Leasing 1(Banco Aliado) | E29: =LEASING!E15 -> 1226.56 | F29: =LEASING!E16 -> 848.73841 | G29: =LEASING!E17 -> 440.6911 | H29: =LEASING!E18 -> 0 | I29: =LEASING!E19 -> 0 | J29: =I29 -> 0
B30: Leasing 2 (Banco Aliado-Llenadora de Liquido) | F30: =LEASING!E37 -> 920.122 | G30: =LEASING!E38 -> 716.53029 | H30: =LEASING!E39 -> 496.24407 | I30: =LEASING!E40 -> 257.89437
B31: Leasing 3(Banco Aliado) | F31: =LEASING!E64 -> 1593.342 | G31: =LEASING!E65 -> 1103.4935 | H31: =LEASING!E66 -> 573.47741 | I31: 0
B32: Leasing 4(Banco Aliado) | F32: =LEASING!E86 -> 795.925 | G32: =LEASING!E87 -> 550.51462 | H32: =LEASING!E88 -> 285.71682 | I32: 0
B33: Leasing 5(Banco Aliado) | G33: =LEASING!E112 -> 3888.32 | H33: =LEASING!E113 -> 3030.2512 | I33: =LEASING!E114 -> 2100.2763 | J33: =LEASING!E115 -> 1092.3694
B34: Leasing 6(Banco General) | F34: =LEASING!E134 -> 6767 | G34: =LEASING!E135 -> 5892.1578 | H34: =LEASING!E136 -> 4928.9566 | I34: =LEASING!E137 -> 3868.472 | J34: =LEASING!E138 -> 2700.8785
B35: Factoring commissions | C35: 24600 | D35: 25149.49 | E35: 0 | F35: 0 | G35: 0 | H35: 0 | I35: 0 | J35: 0 | O35: 15000 | S35: =E35/O35 -> 0
B36: Mortgage/Commercial Loan Payment | D36: 0 | E36: 0 | F36: 0 | G36: =LOANS!#REF! -> #REF! | H36: =LOANS!#REF! -> #REF! | I36: =LOANS!#REF! -> #REF! | J36: =LOANS!#REF! -> #REF!
B38: UTILIDADES ANTES DE TAXES | C38: =C24-C26 -> 14618 | D38: =D24-D26 -> #REF! | E38: =E24-E26 -> 112176.04 | F38: =F24-F26 -> #REF! | G38: =G24-G26 -> #REF! | H38: =H24-H26 -> #REF! | I38: =I24-I26 -> #REF! | J38: =J24-J26 -> #REF! | O38: 229572.97 | Q38: =E38-O38 -> -117396.93 | S38: =E38/O38 -> 0.48862914
B40: TAXES (CAIR) | C40: 4385 | D40: =IF(D9>0,D9*0.014,0) -> #REF! | E40: =IF(E9>0,E9*0.014,0) -> 9325.876 | F40: =IF(F9>0,F9*0.014,0) -> 14256.494 | G40: =IF(G9>0,G9*0.014,0) -> 20401.822 | H40: =IF(H9>0,H9*0.014,0) -> 26165.323 | I40: =IF(I9>0,I9*0.014,0) -> 30412.105 | J40: =IF(J9>0,J9*0.014,0) -> 34998.628 | O40: 9456.1425 | Q40: =E40-O40 -> -130.2665 | S40: =E40/O40 -> 0.98622414
B41: Taxes (Metodo Anterior) | F41: =IF(F38>0,F38*0.3) -> #REF! | G41: =IF(G38>0,G38*0.3,0) -> #REF! | H41: =IF(H38>0,H38*0.3,0) -> #REF! | I41: =IF(I38>0,I38*0.3,0) -> #REF! | J41: =IF(J38>0,J38*0.3,0) -> #REF! | O41: 68871.89 | Q41: =E41-O41 -> -68871.89 | S41: =E41/O41 -> 0
B42: NET PROFIT | C42: =IF(C40>C41,C38-C40,C38-C41) -> 10233 | D42: =IF(D40>D41,D38-D40,D38-D41) -> #REF! | E42: =IF(E40>E41,E38-E40,E38-E41) -> 102850.16 | F42: =F24-F26-F40 -> #REF! | G42: =G24-G26-G40 -> #REF! | H42: =H24-H26-H40 -> #REF! | I42: =I24-I26-I40 -> #REF! | J42: =J24-J26-J40 -> #REF! | O42: 160701.08 | Q42: =E42-O42 -> -57850.912 | S42: =E42/O42 -> 0.64000918
B45: Gross Margin | C45: =+C13/C9 -> 0.66999987 | D45: =+D13/D9 -> #REF! | E45: =+E13/E9 -> 0.60044075 | F45: =F13/F9 -> 0.56241499 | G45: =G13/G9 -> 0.48559649 | H45: =H13/H9 -> 0.54953368 | I45: =I13/I9 -> 0.56854444 | J45: =J13/J9 -> #REF! | O45: 0.72657239 | Q45: =E45-O45 -> -0.12613164
B46: Margin Operativo | C46: =C24/C9 -> 0.22658751 | D46: =D24/D9 -> #REF! | E46: =E24/E9 -> 0.24890788 | F46: =F24/F9 -> #REF! | G46: =G24/G9 -> #REF! | H46: =H24/H9 -> #REF! | I46: =I24/I9 -> #REF! | J46: =J24/J9 -> #REF!
B47: Margin Neto | C47: =C42/C9 -> 0.044087045 | D47: =D42/D9 -> #REF! | E47: =E42/E9 -> 0.15439861 | F47: =F42/F9 -> #REF! | G47: =G42/G9 -> #REF! | H47: =H42/H9 -> #REF! | I47: =I42/I9 -> #REF! | J47: =J42/J9 -> #REF! | O47: 0.36831314 | Q47: =E46-O47 -> -0.11940526
O49: 0.23792102 | Q49: =E47-O49 -> -0.083522408
...

Sheet Financial Objectives
C1: <<CONTENTS
C3: FINANCIAL OBJECTIVES - 3 YEARS (2014-2016) | G3: OPERATING OBJECTIVES
C6: REVENUE GOALS | G6: PRODUCTION GOALS
C8: Focus on the industrial market, as it has a | G8: Improve the quality of packing boxes
C9: much higher sales margin than supermarket customers | G9: Improve storage
C10: and that sales margin can be sustained with faster collections | G10: Reduce product waste
C11: Achieve sales increases of 40%-18% for industrial customers | G11: Reduce returns
C12: Achieve sales increases of 11%-8% for supermarket customers | G12: Better inventory and finished goods management
C14: COST GOALS | G14: ACCOUNTING GOALS
C16: Goal: waste reduction | G16: Accounting is already in order
C17: Goal: reduce cost of sales, especially for industrial customers
C18: Maintain stability for supermarkets
C20: EXPENSE GOALS | G20: FINANCE AND BI GOALS
C22: Reduce total expenses from 6% to 3% | G22: Maintain orderly, clean, and transparent finances
C23: Keep personnel growth under control | G23: Incorporate and train staff in principles of
G24: BI (dashboards, databases, pivot tables)
C26: LIABILITY GOALS
C27: Properly manage the consolidated loan
C28: Use a maximum of $200,000 from the revolving credit line
C30: ASSET GOALS
C31: Purchase an automatic gallon filler and labeling machine
C32: by the end of 2014
C34: CAPITAL GOALS
C35: The company is trying to increase annual profits
C36: to be able to recapitalize the company

Sheet Revenue
A1: Company Suquimsa
A2: REVENUE
C3: (Values in Dollars)
B6: Delta Comercial (Supermarkets) | F6: =F19/E19-1 -> -0.18506589 | G6: =G19/F19-1 -> 0.1091173 | H6: 0.08 | I6: 0.08
B7: Delta Industrial (Companies) | F7: =F20/E20-1 -> 0.20740362 | G7: 0.386 | H7: 0.2 | I7: 0.18
B8: % of Commercial Revenue (Supermarkets) | E8: =E19/E$18 -> 0.45885481 | F8: =F19/F$18 -> 0.36322364 | G8: =G19/G$18 -> 0.31411916 | H8: =H19/H$18 -> 0.29187562 | I8: =I19/I$18 -> 0.27391576
B9: % of Industrial Revenue (Companies) | E9: =E20/E$18 -> 0.54114519 | F9: =F20/F$18 -> 0.63466214 | G9: =G20/G$18 -> 0.68588084 | H9: =H20/H$18 -> 0.70812438 | I9: =I20/I$18 -> 0.72608424
B10: % Change in Tot Revenue | E10: =(E18/D18)-100% -> -0.09590637 | F10: =(F18/E18)-100% -> 0.029493672 | G10: =(G18/F18)-100% -> 0.28249935 | H10: =(H18/G18)-100% -> 0.1623057 | I10: =(I18/H18)-100% -> 0.15081244
B12: <<Contenido | F12: ACTUAL | G12: PROJECTED
D13: =E13+1 -> 2 | E13: 1 | G13: 1 | H13: =G13+1 -> 2 | I13: =H13+1 -> 3
D14: =$F$14-D13 -> 2011 | E14: =$F$14-E13 -> 2012 | F14: 2013 | G14: =$F$14+G13 -> 2014 | H14: =$F$14+H13 -> 2015 | I14: =$F$14+I13 -> 2016
B17: TOTAL year-over-year sales growth
B18: Total Sales | D18: ='P&L (New)'!B8 -> 1565683 | E18: =SUM(E19:E21) -> 1415524 | F18: =SUM(F19:F21) -> 1457273 | G18: =SUM(G19:G21) -> 1868951.7 | H18: =SUM(H19:H21) -> 2172293.2 | I18: =SUM(I19:I21) -> 2499902
B19: Sales Comercial (Supermercados) | E19: 649520 | F19: 529316 | G19: 587073.53 | H19: =G19*(1+H6) -> 634039.42 | I19: =H19*(1+I6) -> 684762.57
B20: Sales Industrial (Empresas) | E20: 766004 | F20: 924876 | G20: =F20*(1+G7) -> 1281878.1 | H20: =G20*(1+H7) -> 1538253.8 | I20: =H20*(1+I7) -> 1815139.4
B21: Detail | F21: 3081
B23: TOTAL SALES REVENUE | D23: =D18 -> 1565683 | E23: =E18 -> 1415524 | F23: =F18 -> 1457273 | G23: =G18 -> 1868951.7 | H23: =H18 -> 2172293.2 | I23: =I18 -> 2499902

Sheet Costs
A1: =Revenue!A1:H1 -> Company Suquimsa
A2: COSTS BY CLIENT TYPE
A3: (Values in Dollars)
B5: Commercial Sales Margin (Supermarkets) | F5: 0.4 | G5: =F5 -> 0.4 | H5: =G5 -> 0.4 | I5: =H5 -> 0.4
B6: Industrial Sales Margin (Companies) | F6: 0.68 | G6: =F6+1% -> 0.69 | H6: =G6+1% -> 0.7 | I6: =H6+1% -> 0.71
B8: Commercial Cost of Sales (Supermarkets) | F8: =1-F5 -> 0.6 | G8: =1-G5 -> 0.6 | H8: =1-H5 -> 0.6 | I8: =1-I5 -> 0.6
B9: Industrial Cost of Sales (Companies) | F9: =1-F6 -> 0.32 | G9: =1-G6 -> 0.31 | H9: =1-H6 -> 0.3 | I9: =1-I6 -> 0.29
B10: TOTAL Cost of Sales | F10: =F18/Revenue!F23 -> 0.42102607 | G10: =G18/Revenue!G23 -> 0.40109456 | H10: =H18/Revenue!H23 -> 0.38756269 | I10: =I18/Revenue!I23 -> 0.37491389
B12: <<Contenido | F12: ACTUAL | G12: PROJECTED
D13: =Revenue!D14 -> 2011 | E13: =Revenue!E14 -> 2012 | F13: =Revenue!F14 -> 2013 | G13: =Revenue!G14 -> 2014 | H13: =Revenue!H14 -> 2015 | I13: =Revenue!I14 -> 2016
B16: Cost Supermercados | F16: =Revenue!F19*F8 -> 317589.6 | G16: =Revenue!G19*G8 -> 352244.12 | H16: =Revenue!H19*H8 -> 380423.65 | I16: =Revenue!I19*I8 -> 410857.54
B17: Cost Empresas | F17: =Revenue!F20*F9 -> 295960.32 | G17: =Revenue!G20*G9 -> 397382.22 | H17: =Revenue!H20*H9 -> 461476.13 | I17: =Revenue!I20*I9 -> 526390.44
B18: TOTAL | D18: =SUM(D16:D17) -> 0 | E18: =SUM(E16:E17) -> 0 | F18: =SUM(F16:F17) -> 613549.92 | G18: =SUM(G16:G17) -> 749626.34 | H18: =SUM(H16:H17) -> 841899.78 | I18: =SUM(I16:I17) -> 937247.98

Sheet Expenses
A1: =Revenue!A1:H1 -> Company Suquimsa
A2: Expenses
A3: (Values in Dollars)
A5: <<Contenido | B5: ACTUAL | C5: PROJECTED | G5: Projected Growth Rates
B6: 2013 | C6: =B6+1 -> 2014 | D6: =C6+1 -> 2015 | E6: =D6+1 -> 2016 | G6: 2014 | H6: =G6+1 -> 2015 | I6: =H6+1 -> 2016
A7: Personnel and Professional Fees | B7: =SUM(B8:B10) -> 387744.34 | C7: =SUM(C8:C10) -> 426518.77 | D7: =SUM(D8:D10) -> 452109.9 | E7: =SUM(E8:E10) -> 465673.2 | G7: =C7/B7-1 -> 0.1 | H7: =D7/C7-1 -> 0.06 | I7: =E7/D7-1 -> 0.03
A8: Salaries | B8: =VLOOKUP(A8,'Income Data - 12 Period'!$A$25:$N$76,14,FALSE) -> 133912.87 | C8: =B8*(1+G8) -> 147304.16 | D8: =C8*(1+H8) -> 156142.41 | E8: =D8*(1+I8) -> 160826.68 | G8: 0.1 | H8: 0.06 | I8: 0.03
A9: Prestaciones laborales | B9: =SUM('Income Data - 12 Period'!N26:N34) -> 203168.65 | C9: =B9*(1+G9) -> 223485.51 | D9: =C9*(1+H9) -> 236894.65 | E9: =D9*(1+I9) -> 244001.49 | G9: 0.1 | H9: 0.06 | I9: 0.03
A10: Servicios Profesionales | B10: =VLOOKUP(A10,'Income Data - 12 Period'!$A$25:$N$76,14,FALSE) -> 50662.82 | C10: =B10*(1+G10) -> 55729.102 | D10: =C10*(1+H10) -> 59072.848 | E10: =D10*(1+I10) -> 60845.034 | G10: 0.1 | H10: 0.06 | I10: 0.03
A11: Common Administrative Expenses | B11: =SUM(B12:B22) -> 152095.92 | C11: =SUM(C12:C22) -> 155496.11 | D11: =SUM(D12:D22) -> 164307.81 | E11: =SUM(E12:E22) -> 170483.45 | G11: =C11/B11-1 -> 0.022355579 | H11: =D11/C11-1 -> 0.056668297 | I11: =E11/D11-1 -> 0.037585809
A12: Articulos de Limpieza | B12: ='Income Data - 12 Period'!N43+'Income Data - 12 Period'!N68 -> 1490.99 | C12: =B12*(1+G12) -> 1565.5395 | D12: =C12*(1+H12) -> 1612.5057 | E12: =D12*(1+I12) -> 1628.6307 | G12: 0.05 | H12: =G12-2% -> 0.03 | I12: =H12-2% -> 0.01
A13: Fuel and Lubricants | B13: =VLOOKUP(A13,'Income Data - 12 Period'!$A$25:$N$76,14,FALSE) -> 23737.77 | C13: =B13*(1+G13) -> 25399.414 | D13: =C13*(1+H13) -> 26669.385 | E13: =D13*(1+I13) -> 27469.466 | G13: 0.07 | H13: =G13-2% -> 0.05 | I13: =H13-2% -> 0.03
A14: Electricity and Water | B14: ='Income Data - 12 Period'!N58+'Income Data - 12 Period'!N59 -> 18106.75 | C14: =B14*(1+G14) -> 19012.088 | D14: =C14*(1+H14) -> 19582.45 | E14: =D14*(1+I14) -> 19778.275 | G14: 0.05 | H14: =G14-2% -> 0.03 | I14: =H14-2% -> 0.01
A15: Multas y Recargos | B15: =VLOOKUP(A15,'Income Data - 12 Period'!$A$25:$N$76,14,FALSE) -> 385.4 | C15: =B15*(1+G15) -> 396.962 | D15: =C15*(1+H15) -> 400.93162 | E15: =D15*(1+I15) -> 396.9223 | G15: 0.03 | H15: =G15-2% -> 0.01 | I15: =H15-2% -> -0.01
A16: utiles de oficina | B16: =VLOOKUP(A16,'Income Data - 12 Period'!$A$25:$N$76,14,FALSE) -> 3617.56 | C16: =B16*(1+G16) -> 3798.438 | D16: =C16*(1+H16) -> 3912.3911 | E16: =D16*(1+I16) -> 3951.5151 | G16: 0.05 | H16: =G16-2% -> 0.03 | I16: =H16-2% -> 0.01
A17: arreglos de oficina | B17: =VLOOKUP(A17,'Income Data - 12 Period'!$A$25:$N$76,14,FALSE) -> 3938.27 | C17: =B17*(1+G17) -> 4135.1835 | D17: =C17*(1+H17) -> 4259.239 | E17: =D17*(1+I17) -> 4301.8314 | G17: 0.05 | H17: =G17-2% -> 0.03 | I17: =H17-2% -> 0.01
A18: Other expenses | B18: =VLOOKUP(A18,'Income Data - 12 Period'!$A$25:$N$76,14,FALSE) -> 900 | C18: =B18*(1+G18) -> 927 | D18: =C18*(1+H18) -> 936.27 | E18: =D18*(1+I18) -> 926.9073 | G18: 0.03 | H18: =G18-2% -> 0.01 | I18: =H18-2% -> -0.01
A19: Car Rentals | B19: =VLOOKUP(A19,'Income Data - 12 Period'!$A$25:$N$76,14,FALSE) -> 6932.23 | C19: 0 | D19: =C19*(1+H19) -> 0 | E19: =D19*(1+I19) -> 0 | G19: 0 | H19: =G19-2% -> -0.02 | I19: =H19-2% -> -0.04
A20: Tools and Small Equipment | B20: =VLOOKUP(A20,'Income Data - 12 Period'!$A$25:$N$76,14,FALSE) -> 614.9 | C20: 0 | D20: =C20*(1+H20) -> 0 | E20: =D20*(1+I20) -> 0 | G20: 0 | H20: =G20-2% -> -0.02 | I20: =H20-2% -> -0.04
A21: Telephone | B21: =VLOOKUP(A21,'Income Data - 12 Period'!$A$25:$N$76,14,FALSE) -> 13477.67 | C21: =B21*(1+G21) -> 13477.67 | D21: =C21*(1+H21) -> 13208.117 | E21: =D21*(1+I21) -> 12679.792 | G21: 0 | H21: =G21-2% -> -0.02 | I21: =H21-2% -> -0.04
A22: Travel Allowance Expenses | B22: =VLOOKUP(A22,'Income Data - 12 Period'!$A$25:$N$76,14,FALSE) -> 78894.38 | C22: =B22*(1+G22) -> 86783.818 | D22: =C22*(1+H22) -> 93726.523 | E22: =D22*(1+I22) -> 99350.115 | G22: 0.1 | H22: =G22-2% -> 0.08 | I22: =H22-2% -> 0.06
A23: Marketing and Advertising Expenses | B23: =SUM(B24:B26) -> 3425.64 | C23: =SUM(C24:C26) -> 2047.9095 | D23: =SUM(D24:D26) -> 2150.305 | E23: =SUM(E24:E26) -> 2257.8202 | G23: =C23/B23-1 -> -0.40218193 | H23: =D23/C23-1 -> 0.05 | I23: =E23/D23-1 -> 0.05
A24: Customer and Employee Attention | B24: =VLOOKUP(A24,'Income Data - 12 Period'!$A$25:$N$76,14,FALSE) -> 1950.39 | C24: =B24*(1+G24) -> 2047.9095 | D24: =C24*(1+H24) -> 2150.305 | E24: =D24*(1+I24) -> 2257.8202 | G24: 0.05 | H24: =G24 -> 0.05 | I24: =H24 -> 0.05
A25: Expenses Publicitarios | B25: =VLOOKUP(A25,'Income Data - 12 Period'!$A$25:$N$76,14,FALSE) -> 645 | C25: 0 | D25: =C25*(1+H25) -> 0 | E25: =D25*(1+I25) -> 0 | G25: 0 | H25: =G25 -> 0 | I25: =H25 -> 0
A26: Suscripciones y Afiliaciones | B26: =VLOOKUP(A26,'Income Data - 12 Period'!$A$25:$N$76,14,FALSE) -> 830.25 | C26: 0 | D26: =C26*(1+H26) -> 0 | E26: =D26*(1+I26) -> 0 | G26: 0 | H26: =G26 -> 0 | I26: =H26 -> 0
A27: Repar. Y Maintenance | B27: =SUM(B28:B30) -> 13569.61 | C27: =SUM(C28:C30) -> 13054.741 | D27: =SUM(D28:D30) -> 12565.615 | E27: =SUM(E28:E30) -> 12100.946 | G27: =C27/B27-1 -> -0.0379428 | H27: =D27/C27-1 -> -0.037467273 | I27: =E27/D27-1 -> -0.036979428
A28: Auto Repair Maintenance | B28: =VLOOKUP(A28,'Income Data - 12 Period'!$A$25:$N$76,14,FALSE) -> 1164.94 | C28: =B28*(1+G28) -> 1164.94 | D28: =C28*(1+H28) -> 1164.94 | E28: =D28*(1+I28) -> 1164.94 | G28: 0 | H28: =G28 -> 0 | I28: =H28 -> 0
A29: Auto Maintenance and Repairs | B29: =VLOOKUP(A29,'Income Data - 12 Period'!$A$25:$N$76,14,FALSE) -> 2107.29 | C29: =B29*(1+G29) -> 2107.29 | D29: =C29*(1+H29) -> 2107.29 | E29: =D29*(1+I29) -> 2107.29 | G29: 0 | H29: =G29 -> 0 | I29: =H29 -> 0
A30: Equipment Maintenance | B30: =VLOOKUP(A30,'Income Data - 12 Period'!$A$25:$N$76,14,FALSE) -> 10297.38 | C30: =B30*(1+G30) -> 9782.511 | D30: =C30*(1+H30) -> 9293.3854 | E30: =D30*(1+I30) -> 8828.7162 | G30: -0.05 | H30: =G30 -> -0.05 | I30: =H30 -> -0.05
A31: Insurance e Taxes | B31: =SUM(B32:B32) -> 30247.81 | C31: =SUM(C32:C32) -> 31457.722 | D31: =SUM(D32:D32) -> 32086.877 | E31: =SUM(E32:E32) -> 32086.877 | G31: =C31/B31-1 -> 0.04 | H31: =D31/C31-1 -> 0.02 | I31: =E31/D31-1 -> 0
A32: Seguro generales | B32: =VLOOKUP(A32,'Income Data - 12 Period'!$A$25:$N$76,14,FALSE) -> 30247.81 | C32: =B32*(1+G32) -> 31457.722 | D32: =C32*(1+H32) -> 32086.877 | E32: =D32*(1+I32) -> 32086.877 | G32: 0.04 | H32: 0.02 | I32: 0
A33: Bank Fees and Other Expenses | B33: =SUM(B34:B35) -> 91034.5 | C33: =SUM(C34:C35) -> 91034.5 | D33: =SUM(D34:D35) -> 91034.5 | E33: =SUM(E34:E35) -> 91034.5 | G33: =C33/B33-1 -> 0 | H33: =D33/C33-1 -> 0 | I33: =E33/D33-1 -> 0
A34: Cargos Bancarios | B34: =VLOOKUP(A34,'Income Data - 12 Period'!$A$25:$N$76,14,FALSE) -> 19010.73 | C34: =B34*(1+G34) -> 19010.73 | D34: =C34*(1+H34) -> 19010.73 | E34: =D34*(1+I34) -> 19010.73 | G34: 0 | H34: =G34 -> 0 | I34: =H34 -> 0
A35: Interest Bancarios | B35: =VLOOKUP(A35,'Income Data - 12 Period'!$A$25:$N$76,14,FALSE) -> 72023.77 | C35: =B35*(1+G35) -> 72023.77 | D35: =C35*(1+H35) -> 72023.77 | E35: =D35*(1+I35) -> 72023.77 | G35: 0 | H35: =G35 -> 0 | I35: =H35 -> 0
A36: TOTAL Expenses | B36: =B7+B11+B23+B27+B31+B33 -> 678117.82 | C36: =C7+C11+C23+C27+C31+C33 -> 719609.76 | D36: =D7+D11+D23+D27+D31+D33 -> 754255.01 | E36: =E7+E11+E23+E27+E31+E33 -> 773636.8 | G36: =C36/B36-1 -> 0.061186918 | H36: =D36/C36-1 -> 0.048144498 | I36: =E36/D36-1 -> 0.025696594

Sheet Personal
A1: =[1]Costos!A1:I1 -> Empresa Suquimsa | I1: =[1]Costos!I1:Q1 -> 0
A2: PERSONAL, WAGES Y SERV. PROFESIONALES | I2: PERSONAL, WAGES Y SERV. PROFESIONALES
A3: ProjectedS Year 2008 | I3: ProjectedS Year 2013
B4: <<Contenido | J4: <<Contenido
A5: PERSONAL CON SUELDO | C5: No. de Empleados | D5: Sueldo por Empleado | F5: Sueldo Total | I5: PERSONAL CON SUELDO | K5: No. de Empleados | L5: Sueldo por Empleado | N5: Sueldo Total
D6: Monthly | E6: Annual | F6: Monthly | G6: Annual | L6: Monthly | M6: Annual | N6: Monthly | O6: Annual
B8: Wages | F8: =SUM(F9:F24) -> 13836 | G8: =SUM(G9:G24) -> 166032 | J8: Wages | N8: =SUM(N9:N24) -> 13436 | O8: =SUM(O9:O24) -> 161232
B9: Gerente General | C9: 1 | D9: 1000 | E9: =D9*12 -> 12000 | F9: =D9*C9 -> 1000 | G9: =(F9*12) -> 12000 | J9: Gerente General | K9: 1 | L9: 1000 | M9: =L9*12 -> 12000 | N9: =L9*K9 -> 1000 | O9: =(N9*12) -> 12000
B10: Gerente Adm. | C10: 1 | D10: 975 | E10: =D10*12 -> 11700 | F10: =D10*C10 -> 975 | G10: =(F10*12) -> 11700 | J10: Gerente Adm. | K10: 1 | L10: 975 | M10: =L10*12 -> 11700 | N10: =L10*K10 -> 975 | O10: =(N10*12) -> 11700
B11: Jefe Production | C11: 1 | D11: 400 | E11: =D11*12 -> 4800 | F11: =D11*C11 -> 400 | G11: =(F11*12) -> 4800 | J11: Jefe Production | K11: 0 | L11: 400 | M11: =L11*12 -> 4800 | N11: =L11*K11 -> 0 | O11: =(N11*12) -> 0
B12: Sup. Saneamiento | C12: 1 | D12: 475 | E12: =D12*12 -> 5700 | F12: =D12*C12 -> 475 | G12: =(F12*12) -> 5700 | J12: Sup. Saneamiento | K12: 1 | L12: 475 | M12: =L12*12 -> 5700 | N12: =L12*K12 -> 475 | O12: =(N12*12) -> 5700
B13: Asistente Supervisor | C13: 2 | D13: 375 | E13: =D13*12 -> 4500 | F13: =D13*C13 -> 750 | G13: =(F13*12) -> 9000 | J13: Asistente Supervisor | K13: 2 | L13: 375 | M13: =L13*12 -> 4500 | N13: =L13*K13 -> 750 | O13: =(N13*12) -> 9000
B14: Operarios Limpieza | C14: 13 | D14: 322 | E14: =D14*12 -> 3864 | F14: =D14*C14 -> 4186 | G14: =(F14*12) -> 50232 | J14: Operarios Limpieza | K14: 13 | L14: 322 | M14: =L14*12 -> 3864 | N14: =L14*K14 -> 4186 | O14: =(N14*12) -> 50232
B15: Mensajero | C15: 3 | D15: 360 | E15: =D15*12 -> 4320 | F15: =D15*C15 -> 1080 | G15: =(F15*12) -> 12960 | J15: Mensajero | K15: 3 | L15: 360 | M15: =L15*12 -> 4320 | N15: =L15*K15 -> 1080 | O15: =(N15*12) -> 12960
B16: Production Operators | C16: 9 | D16: 322 | E16: =D16*12 -> 3864 | F16: =D16*C16 -> 2898 | G16: =(F16*12) -> 34776 | J16: Production Operators | K16: 9 | L16: 322 | M16: =L16*12 -> 3864 | N16: =L16*K16 -> 2898 | O16: =(N16*12) -> 34776
B17: Asistente de contabilidad | C17: 1 | D17: 350 | E17: =D17*12 -> 4200 | F17: =D17*C17 -> 350 | G17: =(F17*12) -> 4200 | J17: Asistente de contabilidad | K17: 1 | L17: 350 | M17: =L17*12 -> 4200 | N17: =L17*K17 -> 350 | O17: =(N17*12) -> 4200
B18: Demostradoras | C18: 0 | D18: 0 | E18: =D18*12 -> 0 | F18: =D18*C18 -> 0 | G18: =(F18*12) -> 0 | J18: Demostradoras | K18: 0 | L18: 0 | M18: =L18*12 -> 0 | N18: =L18*K18 -> 0 | O18: =(N18*12) -> 0
B19: Contador | C19: 1 | D19: 600 | E19: =D19*12 -> 7200 | F19: =D19*C19 -> 600 | G19: =(F19*12) -> 7200 | J19: Contador | K19: 1 | L19: 600 | M19: =L19*12 -> 7200 | N19: =L19*K19 -> 600 | O19: =(N19*12) -> 7200
B20: Secretaria recepcionista | C20: 1 | D20: 322 | E20: =D20*12 -> 3864 | F20: =D20*C20 -> 322 | G20: =(F20*12) -> 3864 | J20: Secretaria recepcionista | K20: 1 | L20: 322 | M20: =L20*12 -> 3864 | N20: =L20*K20 -> 322 | O20: =(N20*12) -> 3864
... B24: Aseador Miscelaneo | C24: 0 | D24: 100 | E24: =D24*12 -> 1200 | F24: =D24*C24 -> 0 | G24: =(F24*12) -> 0 | J24: Aseador Miscelaneo | K24: 0 | L24: 100 | M24: =L24*12 -> 1200 | N24: =L24*K24 -> 0 | O24: =(N24*12) -> 0
B25: Prestaciones sociales (30%) | F25: =F8*0.3 -> 4150.8 | G25: =G8*0.3 -> 49809.6 | J25: Prestaciones sociales (30%) | N25: =N8*0.3 -> 4030.8 | O25: =O8*0.3 -> 48369.6
B27: TOTALES | C27: =SUM(C10:C24) -> 35 | F27: =(F8+F25) -> 17986.8 | G27: =(G8+G25) -> 215841.6 | J27: TOTALES | K27: =SUM(K10:K24) -> 34 | N27: =(N8+N25) -> 17466.8 | O27: =(O8+O25) -> 209601.6
A30: SERVICIOS PROFESIONALES | C30: No. de Empleados | D30: Unitario | F30: Total | I30: SERVICIOS PROFESIONALES | K30: No. de Empleados | L30: Unitario | N30: Total
D31: Monthly | E31: Annual | F31: Monthly | G31: Annual | L31: Monthly | M31: Annual | N31: Monthly | O31: Annual
B33: Pago por Servicios | F33: =SUM(F34:F37) -> 0 | G33: =SUM(G34:G37) -> 0 | J33: Pago por Servicios | N33: =SUM(N34:N37) -> 0 | O33: =SUM(O34:O37) -> 0
B35: Correccion estilo | C35: 1 | D35: 0 | E35: =D35*12 -> 0 | F35: =D35*C35 -> 0 | G35: =(F35*12) -> 0 | J35: Correccion estilo | K35: 1 | L35: 0 | M35: =L35*12 -> 0 | N35: =L35*K35 -> 0 | O35: =(N35*12) -> 0
B36: Diseno | C36: 1 | D36: 0 | E36: =D36*12 -> 0 | F36: =D36*C36 -> 0 | G36: =(F36*12) -> 0 | J36: Diseno | K36: 1 | L36: 0 | M36: =L36*12 -> 0 | N36: =L36*K36 -> 0 | O36: =(N36*12) -> 0
B37: Fotografias | C37: 1 | D37: 0 | E37: =D37*12 -> 0 | F37: =D37*C37 -> 0 | G37: =(F37*12) -> 0 | J37: Fotografias | K37: 1 | L37: 0 | M37: =L37*12 -> 0 | N37: =L37*K37 -> 0 | O37: =(N37*12) -> 0
B39: TOTALES | C39: =SUM(C34:C37) -> 3 | F39: =F33 -> 0 | G39: =G33 -> 0 | J39: TOTALES | K39: =SUM(K34:K37) -> 3 | N39: =N33 -> 0 | O39: =O33 -> 0
B42: TOTAL DE WAGES Y | F42: Monthly | G42: Annual | J42: TOTAL DE WAGES Y | N42: Monthly | O42: Annual
B43: SERVICIOS PROFESIONALES | F43: =F27+F39 -> 17986.8 | G43: =G27+G39 -> 215841.6 | J43: SERVICIOS PROFESIONALES | N43: =N27+N39 -> 17466.8 | O43: =O27+O39 -> 209601.6

Sheet LOANS
A1: =Expenses!A1 -> Company Suquimsa
A2: FINANCING
A3: (Values in Dollars)
A5: Amount = | C5: 700000 | E5: MONTHLY PAYMENT | F5: =+F17/12 -> 8492.9916
A6: Rate = | C6: 0.074862 | E6: TOTAL PAYMENT | F6: =F27 -> 1019159
A7: Years = | C7: 10 | E7: INTEREST PAYMENT | F7: =F6-C5 -> 319158.99
A10: <<Contenido
A11: LOAN CONSOLIDADO MULTIBANK
A12: Years | C12: Debt Balance at Beginning of Year | D12: Loan Amortization | E12: Loan Interest Payment | F12: Total Payment: Amortization plus Interest | G12: Debt Balance at End of Year | H12: MONTHLY PAYMENT
H16: =F17/12 -> 8492.9916
A17: 2013 | C17: =C5 -> 700000 | D17: =(F17-E17) -> 49512.499 | E17: =(C17*$C$6) -> 52403.4 | F17: =PMT($C$6,$C$7,-$C$17) -> 101915.9 | G17: =(C17-D17) -> 650487.5
A18: =A17+1 -> 2014 | C18: =G17 -> 650487.5 | D18: =(F18-E18) -> 53219.104 | E18: =(C18*$C$6) -> 48696.795 | F18: =PMT($C$6,$C$7,-$C$17) -> 101915.9 | G18: =(C18-D18) -> 597268.4
A19: =A18+1 -> 2015 | C19: =G18 -> 597268.4 | D19: =(F19-E19) -> 57203.192 | E19: =(C19*$C$6) -> 44712.707 | F19: =PMT($C$6,$C$7,-$C$17) -> 101915.9 | G19: =(C19-D19) -> 540065.21
A20: =A19+1 -> 2016 | C20: =G19 -> 540065.21 | D20: =(F20-E20) -> 61485.537 | E20: =(C20*$C$6) -> 40430.361 | F20: =PMT($C$6,$C$7,-$C$17) -> 101915.9 | G20: =(C20-D20) -> 478579.67
A21: =A20+1 -> 2017 | C21: =G20 -> 478579.67 | D21: =(F21-E21) -> 66088.468 | E21: =(C21*$C$6) -> 35827.431 | F21: =PMT($C$6,$C$7,-$C$17) -> 101915.9 | G21: =(C21-D21) -> 412491.2
A22: =A21+1 -> 2018 | C22: =G21 -> 412491.2 | D22: =(F22-E22) -> 71035.983 | E22: =(C22*$C$6) -> 30879.916 | F22: =PMT($C$6,$C$7,-$C$17) -> 101915.9 | G22: =(C22-D22) -> 341455.22
A23: =A22+1 -> 2019 | C23: =G22 -> 341455.22 | D23: =(F23-E23) -> 76353.878 | E23: =(C23*$C$6) -> 25562.021 | F23: =PMT($C$6,$C$7,-$C$17) -> 101915.9 | G23: =(C23-D23) -> 265101.34
A24: =A23+1 -> 2020 | C24: =G23 -> 265101.34 | D24: =(F24-E24) -> 82069.882 | E24: =(C24*$C$6) -> 19846.016 | F24: =PMT($C$6,$C$7,-$C$17) -> 101915.9 | G24: =(C24-D24) -> 183031.46
A25: =A24+1 -> 2021 | C25: =G24 -> 183031.46 | D25: =(F25-E25) -> 88213.798 | E25: =(C25*$C$6) -> 13702.101 | F25: =PMT($C$6,$C$7,-$C$17) -> 101915.9 | G25: =(C25-D25) -> 94817.659
A26: =A25+1 -> 2022 | C26: =G25 -> 94817.659 | D26: =(F26-E26) -> 94817.659 | E26: =(C26*$C$6) -> 7098.2396 | F26: =PMT($C$6,$C$7,-$C$17) -> 101915.9 | G26: =(C26-D26) -> 5.8207661e-11
A27: TOTAL | F27: =SUM(F17:F26) -> 1019159

Sheet P&L (New)
B1: Company Suquimsa
B2: Income Statement
B3: (Values in Dollars)
B5: HISTORICAL | D5: YTD | E5: PROJECTED
B6: =+[2]balance!F7 -> 2011 | C6: =+[2]balance!D7 -> 2012 | D6: 2013 | E6: =D6+1 -> 2014 | F6: =E6+1 -> 2015 | G6: =F6+1 -> 2016
A8: Total Revenue | B8: 1565683 | C8: 1431634.3 | D8: =Revenue!F18 -> 1457273 | E8: =Revenue!G23 -> 1868951.7 | F8: =Revenue!H23 -> 2172293.2 | G8: =Revenue!I23 -> 2499902
A10: Cost of Sales | B10: =+[2]Hoja2!Y17 -> 874044.87 | C10: =+[2]Hoja2!H17 -> 724227.09 | D10: =Costs!F18 -> 613549.92 | E10: =Costs!G18 -> 749626.34 | F10: =Costs!H18 -> 841899.78 | G10: =Costs!I18 -> 937247.98
A12: Gross Profit | B12: =B8-B10 -> 691638.1 | C12: =C8-C10 -> 707407.18 | D12: =D8-D10 -> 843723.08 | E12: =E8-E10 -> 1119325.3 | F12: =F8-F10 -> 1330393.4 | G12: =G8-G10 -> 1562654
A14: Expenses | B14: =B15+B20+B30+B33+B36+B40 -> 502763.41 | C14: =C15+C20+C30+C33+C36+C40 -> 434102.06 | D14: =D15+D20+D30+D33+D36+D40 -> 587083.32 | E14: =E15+E20+E30+E33+E36+E40 -> 628575.26 | F14: =F15+F20+F30+F33+F36+F40 -> 663220.51 | G14: =G15+G20+G30+G33+G36+G40 -> 682602.3
A15: Personnel and Professional Fees* | B15: =SUM(B16:B18) -> 319866.6 | C15: =SUM(C16:C18) -> 250301.13 | D15: =Expenses!B7 -> 387744.34 | E15: =Expenses!C7 -> 426518.77 | F15: =Expenses!D7 -> 452109.9 | G15: =Expenses!E7 -> 465673.2
A16: Salario y beneficios a los empleados | B16: 169409.55 | C16: 200980.47 | D16: =SUM(D17:D18) -> 0
A17: Prestaciones laborales | B17: =+[2]Hoja2!Y28 -> 23418.65 | C17: =+[2]Hoja2!H28 -> 27963.55
A18: Professional Fees Profesionales | B18: =+[2]Hoja2!Y48 -> 127038.4 | C18: =+[2]Hoja2!H48 -> 21357.11
A20: Operating Expenses | B20: =SUM(B21:B28) -> 69213.48 | C20: =SUM(C21:C28) -> 90702.82 | D20: =Expenses!B11 -> 152095.92 | E20: =Expenses!C11 -> 155496.11 | F20: =Expenses!D11 -> 164307.81 | G20: =Expenses!E11 -> 170483.45
A21: Rent | B21: =+[2]Hoja2!Y59 -> 0 | C21: =+[2]Hoja2!H59 -> 232.51
A22: Travel Allowance and Transportation | B22: =+[2]Hoja2!Y26 -> 1876.81 | C22: =+[2]Hoja2!H26 -> 25313.96
A23: Travel and Meals Expense | B23: =+[2]Hoja2!Y66 -> 6384.98 | C23: =+[2]Hoja2!H66 -> 2244.64
A24: Comunicaciones | B24: =+[2]Hoja2!Y63 -> 12362.01 | C24: =+[2]Hoja2!H63 -> 13012.76
A25: Luz | B25: =+[2]Hoja2!Y61 -> 16281.82 | C25: =+[2]Hoja2!H61 -> 15842.94
A26: Water | B26: =+[2]Hoja2!Y62 -> 1319.39 | C26: =+[2]Hoja2!H62 -> 2555.88
A27: Utiles de Oficina y Computo | B27: =+[2]Hoja2!Y56 -> 4104.29 | C27: =+[2]Hoja2!H56 -> 2377.98
A28: Fuel and Lubricants | B28: =+[2]Hoja2!Y34 -> 26884.18 | C28: =+[2]Hoja2!H34 -> 29122.15
A30: Marketing and advertising expenses | B30: =B31 -> 12773.22 | C30: =C31 -> 7918.24 | D30: =Expenses!B23 -> 3425.64 | E30: =Expenses!C23 -> 2047.9095 | F30: =Expenses!D23 -> 2150.305 | G30: =Expenses!E23 -> 2257.8202
A31: Announcements and Advertising | B31: =+[2]Hoja2!Y58 -> 12773.22 | C31: =+[2]Hoja2!H58 -> 7918.24
A33: Repairs and Maintenance | B33: =+B34 -> 51983.61 | C33: =+C34 -> 19027.07 | D33: =Expenses!B27 -> 13569.61 | E33: =Expenses!C27 -> 13054.741 | F33: =Expenses!D27 -> 12565.615 | G33: =Expenses!E27 -> 12100.946
A34: Equipment and Facilities Repairs and Maintenance | B34: =+[2]Hoja2!Y51 -> 51983.61 | C34: =+[2]Hoja2!H51 -> 19027.07
A36: Insurance e Taxes | B36: =SUM(B37:B38) -> 50384.99 | C36: =SUM(C37:C38) -> 49059.59 | D36: =Expenses!B31 -> 30247.81 | E36: =Expenses!C31 -> 31457.722 | F36: =Expenses!D31 -> 32086.877 | G36: =Expenses!E31 -> 32086.877
A37: Insurance generales | B37: =+[2]Hoja2!Y46 -> 21929.76 | C37: =+[2]Hoja2!H46 -> 23394.47
A38: Taxes | B38: =+[2]Hoja2!Y39+480.93 -> 28455.23 | C38: =+[2]Hoja2!H39 -> 25665.12
A40: Other Income and Other Expenses | B40: =SUM(B41:B43) -> -1458.49 | C40: =SUM(C41:C43) -> 17093.21 | D40: =SUM(D41:D43) -> 0 | E40: =SUM(E41:E43) -> 0 | F40: =SUM(F41:F43) -> 0 | G40: =SUM(G41:G43) -> 0
A41: Other Income | B41: -28876.26 | C41: -6045
A42: Other Operating Expenses | B42: =+[2]Hoja2!Y32 -> 26895.71 | C42: =+[2]Hoja2!H32 -> 22853.21
A43: Expenses no deducibles | B43: =+[2]Hoja2!Y27 -> 522.06 | C43: =+[2]Hoja2!H27 -> 285 | D43: 0
A45: EBITDA | B45: =+B12-B14 -> 188874.69 | C45: =+C12-C14 -> 273305.12 | D45: =+D12-D14 -> 256639.76 | E45: =+E12-E14 -> 490750.07 | F45: =+F12-F14 -> 667172.89 | G45: =+G12-G14 -> 880051.74
A47: Depreciation and Amortization | B47: =+[2]Hoja2!Y38+7044.25 -> 52540.36 | C47: =+[2]Hoja2!H38 -> 80331.23 | D47: =C47*90% -> 72298.107 | E47: =D47*118% -> 85311.766 | F47: =E47*90% -> 76780.59 | G47: =F47*90% -> 69102.531
A48: Bank Fees and Other Expenses | B48: =SUM(B49:B50) -> 62369.46 | C48: =SUM(C49:C50) -> 58377.81 | D48: =SUM(D49:D50) -> 91034.5 | E48: =SUM(E49:E50) -> 91034.5 | F48: =SUM(F49:F50) -> 91034.5 | G48: =SUM(G49:G50) -> 91034.5
A49: Costs Financial, netos | B49: 62369.46 | C49: 58377.81 | D49: =Expenses!B33 -> 91034.5 | E49: =Expenses!C33 -> 91034.5 | F49: =Expenses!D33 -> 91034.5 | G49: =Expenses!E33 -> 91034.5
A52: Income Tax
A53: Corriente | B53: =18512.46+287.08 -> 18799.54 | C53: 12470.25 | D53: 0 | E53: 0 | F53: 0 | G53: 0
A54: Diferido | B54: 0 | C54: 21250 | D54: 0 | E54: 0 | F54: 0 | G54: 0
...

Sheet P&L Visuals

Sheet Income Data - 12 Period
B1: Ene | C1: Feb | D1: Mar | E1: Abr | F1: May | G1: Jun | H1: Jul | I1: Ago | J1: Sep | K1: Oct | L1: Nov | M1: Dic | N1: TOTAL
A2: Revenues
A3: Sales | B3: 100016.34 | C3: 123715.1 | D3: 91259.78 | E3: 134069.37 | F3: 140676.76 | G3: 124228.07 | H3: 124443.39 | I3: 133914.33 | J3: 96938.73 | K3: 147528.91 | L3: 130791.46 | M3: 8853.86 | N3: =SUM(B3:M3) -> 1356436.1
A4: Other Income | B4: 0 | C4: 0 | D4: 0 | E4: 0 | F4: 0 | G4: 0 | H4: 0 | I4: 6.89 | J4: 0 | K4: 0 | L4: 0 | M4: 0 | N4: =SUM(B4:M4) -> 6.89
A5: Sales Discounts | B5: -651.82 | C5: 0 | D5: -683.64 | E5: -432.02 | F5: -688.34 | G5: 0 | H5: -6.96 | I5: 0 | J5: -947.64 | K5: 0 | L5: -320 | M5: 0 | N5: =SUM(B5:M5) -> -3730.42
A6: Interest Ganados | B6: 0 | C6: 0 | D6: 0 | E6: 0 | F6: 0 | G6: 0 | H6: 0 | I6: 0 | J6: 0 | K6: 0 | L6: 0.3 | M6: 0 | N6: =SUM(B6:M6) -> 0.3
A8: Total Revenues | B8: =ROUND(SUBTOTAL(9, B2:B7), 5) -> 99364.52 | C8: =ROUND(SUBTOTAL(9, C2:C7), 5) -> 123715.1 | D8: =ROUND(SUBTOTAL(9, D2:D7), 5) -> 90576.14 | E8: =ROUND(SUBTOTAL(9, E2:E7), 5) -> 133637.35 | F8: =ROUND(SUBTOTAL(9, F2:F7), 5) -> 139988.42 | G8: =ROUND(SUBTOTAL(9, G2:G7), 5) -> 124228.07 | H8: =ROUND(SUBTOTAL(9, H2:H7), 5) -> 124436.43 | I8: =ROUND(SUBTOTAL(9, I2:I7), 5) -> 133921.22 | ... M8: =ROUND(SUBTOTAL(9, M2:M7), 5) -> 8853.86 | N8: =SUM(B8:M8) -> 1352712.9
A11: Cost of Sales
A12: Cost of Sales | B12: 45131.22 | C12: 45450.83 | D12: 38545.06 | E12: 52158.22 | F12: 62097.64 | G12: 47696.24 | H12: 52125 | I12: 52098.93 | J12: 37095.4 | K12: 59081.55 | L12: 52623.96 | M12: 4558.84 | N12: =SUM(B12:M12) -> 548662.89
A13: Otros Costs | B13: 646.38 | C13: 507.1 | D13: 12 | E13: 261.88 | F13: 292 | G13: 210 | H13: 1403.21 | I13: 8660.42 | J13: 47 | K13: 1623.15 | L13: 1658.76 | M13: 35 | N13: =SUM(B13:M13) -> 15356.9
A14: Purchase Discount | B14: 0 | C14: -39.1 | D14: 0 | E14: 0 | F14: -10.79 | G14: 0 | H14: 0 | I14: 0 | J14: 0 | K14: 0 | L14: 0 | M14: 0 | N14: =SUM(B14:M14) -> -49.89
A15: Purchases exentas | B15: 0 | C15: 9.8 | D15: 0 | E15: 0 | F15: 0 | G15: 0 | H15: 0 | I15: 0 | J15: 0 | K15: 0 | L15: 0 | M15: 0 | N15: =SUM(B15:M15) -> 9.8
A16: Safety Equipment | B16: 0 | C16: 74.76 | D16: 0 | E16: 0 | F16: 13.8 | G16: 0 | H16: 10 | I16: 70.72 | J16: 11.85 | K16: 191.87 | L16: 0 | M16: 0 | N16: =SUM(B16:M16) -> 373
A17: Limpieza Carnicerias | B17: 0 | C17: 0 | D17: 0 | E17: 0 | F17: 0 | G17: 0 | H17: 0 | I17: 630 | J17: 630 | K17: 630 | L17: 900 | M17: 0 | N17: =SUM(B17:M17) -> 2790
A18: Entrega de Mercancias | B18: 0 | C18: 0 | D18: 0 | E18: 0 | F18: 0 | G18: 0 | H18: 0 | I18: 0 | J18: 0 | K18: 0 | L18: 1854.29 | M18: 0 | N18: =SUM(B18:M18) -> 1854.29
A20: Total Cost of Sales | B20: =ROUND(SUBTOTAL(9, B10:B19), 5) -> 45777.6 | C20: =ROUND(SUBTOTAL(9, C10:C19), 5) -> 46003.39 | D20: =ROUND(SUBTOTAL(9, D10:D19), 5) -> 38557.06 | E20: =ROUND(SUBTOTAL(9, E10:E19), 5) -> 52420.1 | F20: =ROUND(SUBTOTAL(9, F10:F19), 5) -> 62392.65 | G20: =ROUND(SUBTOTAL(9, G10:G19), 5) -> 47906.24 | H20: =ROUND(SUBTOTAL(9, H10:H19), 5) -> 53538.21 | I20: =ROUND(SUBTOTAL(9, I10:I19), 5) -> 61460.07 | ... M20: =ROUND(SUBTOTAL(9, M10:M19), 5) -> 4593.84 | N20: =SUM(B20:M20) -> 568996.99
A22: Gross Profit | B22: =-(ROUND(-B8+B20, 5)) -> 53586.92 | C22: =-(ROUND(-C8+C20, 5)) -> 77711.71 | D22: =-(ROUND(-D8+D20, 5)) -> 52019.08 | E22: =-(ROUND(-E8+E20, 5)) -> 81217.25 | F22: =-(ROUND(-F8+F20, 5)) -> 77595.77 | G22: =-(ROUND(-G8+G20, 5)) -> 76321.83 | H22: =-(ROUND(-H8+H20, 5)) -> 70898.22 | I22: =-(ROUND(-I8+I20, 5)) -> 72461.15 | ... M22: =-(ROUND(-M8+M20, 5)) -> 4260.02 | N22: =SUM(B22:M22) -> 783715.88
A24: Expenses
A25: Salaries | B25: 12230.8 | C25: 11600.41 | D25: 11250.77 | E25: 11559.28 | F25: 11121.21 | G25: 11092.08 | H25: 10708.14 | I25: 12861.52 | J25: 14213.61 | K25: 13865.82 | L25: 13409.23 | M25: 0 | N25: =SUM(B25:M25) -> 133912.87
A26: Vacaciones | B26: 1293.58 | C26: 1197.53 | D26: 1165.38 | E26: 1157.14 | F26: 1298.4 | G26: 1091.18 | H26: 1071.14 | I26: 1248.45 | J26: 1378.07 | K26: 1429.31 | L26: 1407.36 | M26: 0 | N26: =SUM(B26:M26) -> 13737.54
A27: Prima de Antiguedad | B27: 294.28 | C27: 274.69 | D27: 283.94 | E27: 259.55 | F27: 302.6 | G27: 230.83 | H27: 253.74 | I27: 275.05 | J27: 291.51 | K27: 330.3 | L27: 320.75 | M27: 0 | N27: =SUM(B27:M27) -> 3117.24
A28: Decimo Tercer Month | B28: 1275.22 | C28: 1190.34 | D28: 1230.4 | E28: 1124.7 | F28: 1311.28 | G28: 1000.24 | H28: 1099.56 | I28: 1191.88 | J28: 1263.23 | K28: 1431.28 | L28: 1389.92 | M28: 0 | N28: =SUM(B28:M28) -> 13508.05
A29: Travel Allowance Expenses | B29: 8011.01 | C29: 8899.7 | D29: 8442.64 | E29: 6567.29 | F29: 8328.09 | G29: 5773.28 | H29: 8789.51 | I29: 6638.03 | J29: 5491.27 | K29: 4910.28 | L29: 5079.28 | M29: 1964 | N29: =SUM(B29:M29) -> 78894.38
A30: Multas y Recargos | B30: 0 | C30: 385.4 | D30: 0 | E30: 0 | F30: 0 | G30: 0 | H30: 0 | I30: 0 | J30: 0 | K30: 0 | L30: 0 | M30: 0 | N30: =SUM(B30:M30) -> 385.4
A31: Seguro Social Patronal | B31: 1880.27 | C31: 45610.52 | D31: 1847.79 | E31: 2100.62 | F31: 1969.04 | G31: 1470.26 | H31: 1616.28 | I31: 2204.22 | J31: 1856.91 | K31: 2130.47 | L31: 2043.09 | M31: 0 | N31: =SUM(B31:M31) -> 64729.47
A32: Seguro Educativo Patronal | B32: 229.48 | C32: 214.18 | D32: 221.41 | E32: 202.37 | F32: 235.96 | G32: 179.97 | H32: 197.86 | I32: 214.46 | J32: 227.35 | K32: 257.56 | L32: 250.11 | M32: 0 | N32: =SUM(B32:M32) -> 2430.71
A33: Riesgos Profesionales Patronal | B33: 321.35 | C33: 5011.74 | D33: 310.06 | E33: 283.42 | F33: 330.44 | G33: 252.06 | H33: 277.09 | I33: 300.35 | J33: 318.33 | K33: 360.68 | L33: 350.26 | M33: 0 | N33: =SUM(B33:M33) -> 8115.78
A34: Commissions | B34: 1998.62 | C34: 1572.45 | D34: 1568.41 | E34: 1169.23 | F34: 3161.24 | G34: 910.85 | H34: 1074.35 | I34: 871.42 | J34: 1995.12 | K34: 1856.64 | L34: 2071.75 | M34: 0 | N34: =SUM(B34:M34) -> 18250.08
A35: Customer and Employee Attention | B35: 170.15 | C35: 776.27 | D35: 2.25 | E35: 378.92 | F35: 0 | G35: 161.2 | H35: 101.6 | I35: 0 | J35: 0 | K35: 0 | L35: 0 | M35: 360 | N35: =SUM(B35:M35) -> 1950.39
A36: Tolls and Transportation | B36: 71 | C36: 160.07 | D36: 284.44 | E36: 54 | F36: 369.96 | G36: 204.8 | H36: 176.2 | I36: 0 | J36: 314.5 | K36: 209 | L36: 243.8 | M36: 0 | N36: =SUM(B36:M36) -> 2087.77
... A76: Arreglos de Oficina | B76: 959.84 | C76: 149 | D76: 231.93 | E76: 0 | F76: 0 | G76: 815 | H76: 0 | I76: 1782.5 | J76: 0 | K76: 0 | L76: 0 | M76: 0 | N76: =SUM(B76:M76) -> 3938.27
A78: Total Expenses | B78: =ROUND(SUBTOTAL(9, B24:B77), 5) -> 46713.02 | C78: =ROUND(SUBTOTAL(9, C24:C77), 5) -> 99129.7 | D78: =ROUND(SUBTOTAL(9, D24:D77), 5) -> 57952.33 | E78: =ROUND(SUBTOTAL(9, E24:E77), 5) -> 52672.99 | F78: =ROUND(SUBTOTAL(9, F24:F77), 5) -> 53480.11 | G78: =ROUND(SUBTOTAL(9, G24:G77), 5) -> 56328.29 | H78: =ROUND(SUBTOTAL(9, H24:H77), 5) -> 49093.32 | I78: =ROUND(SUBTOTAL(9, I24:I77), 5) -> 57824.17 | ... M78: =ROUND(SUBTOTAL(9, M24:M77), 5) -> 16263.96 | N78: =SUM(B78:M78) -> 670462.64
A80: Net Income | B80: =-(ROUND(-B22+B78, 5)) -> 6873.9 | C80: =-(ROUND(-C22+C78, 5)) -> -21417.99 | D80: =-(ROUND(-D22+D78, 5)) -> -5933.25 | E80: =-(ROUND(-E22+E78, 5)) -> 28544.26 | F80: =-(ROUND(-F22+F78, 5)) -> 24115.66 | G80: =-(ROUND(-G22+G78, 5)) -> 19993.54 | H80: =-(ROUND(-H22+H78, 5)) -> 21804.9 | I80: =-(ROUND(-I22+I78, 5)) -> 14636.98 | ... M80: =-(ROUND(-M22+M78, 5)) -> -12003.94 | N80: =SUM(B80:M80) -> 113253.24

Sheet LEASING
A3: COMPANY SUQIMSA
A4: (Leasing 1 ) Banco Aliado
D5: *este leasing se obtuvo en Oct del 2006
A6: Tasa = | C6: 0.08
A7: Years = | C7: 3
A9: FINACIAMIENTO
A10: Years | C10: Debt Balance at Beginning of Year | D10: Amortization del Loan | E10: Loan Interest Payment | F10: Total Pagado Amortization mas Inter AnnualIDAD | G10: Debt Balance at End of Year | H10: MONTHLYIDAD
F11: MAS
H14: =F15/12 -> 495.77749
A15: 2007 | C15: 15332 | D15: =(F15-E15) -> 4722.7698 | E15: =(C15*$C$6) -> 1226.56 | F15: =PMT($C$6,$C$7,-$C$15) -> 5949.3298 | G15: =(C15-D15) -> 10609.23
A16: 2008 | C16: =G15 -> 10609.23 | D16: =(F16-E16) -> 5100.5914 | E16: =(C16*$C$6) -> 848.73841 | F16: =PMT($C$6,$C$7,-$C$15) -> 5949.3298 | G16: =(C16-D16) -> 5508.6387
A17: =A16+1 -> 2009 | C17: =G16 -> 5508.6387 | D17: =(F17-E17) -> 5508.6387 | E17: =(C17*$C$6) -> 440.6911 | F17: =PMT($C$6,$C$7,-$C$15) -> 5949.3298 | G17: =(C17-D17) -> -4.5474735e-12
A22: TOTAL | F22: =SUM(F15:F19) -> 17847.99
A25: COMPANY SUQIMSA
A26: (Leasing 2 ) Banco Aliado
D27: *este leasing se obtuvo en Abr del 2007
A28: Tasa = | C28: 0.082
A29: Years = | C29: 4
A31: FINACIAMIENTO
A32: Years | C32: Debt Balance at Beginning of Year | D32: Amortization del Loan | E32: Loan Interest Payment | F32: Total Pagado Amortization mas Inter AnnualIDAD | G32: Debt Balance at End of Year | H32: MONTHLYIDAD
F33: MAS
H36: =F37/12 -> 283.57897
A37: 2007 | C37: 11221 | D37: =(F37-E37) -> 2482.8257 | E37: =(C37*$C$28) -> 920.122 | F37: =PMT($C$28,$C$29,-$C$37) -> 3402.9477 | G37: =(C37-D37) -> 8738.1743
A38: =A37+1 -> 2008 | C38: =G37 -> 8738.1743 | D38: =(F38-E38) -> 2686.4174 | E38: =(C38*$C$28) -> 716.53029 | F38: =PMT($C$28,$C$29,-$C$37) -> 3402.9477 | G38: =(C38-D38) -> 6051.7569
A39: =A38+1 -> 2009 | C39: =G38 -> 6051.7569 | D39: =(F39-E39) -> 2906.7036 | E39: =(C39*$C$28) -> 496.24407 | F39: =PMT($C$28,$C$29,-$C$37) -> 3402.9477 | G39: =(C39-D39) -> 3145.0533
A40: =A39+1 -> 2010 | C40: =G39 -> 3145.0533 | D40: =(F40-E40) -> 3145.0533 | E40: =(C40*$C$28) -> 257.89437 | F40: =PMT($C$28,$C$29,-$C$37) -> 3402.9477 | G40: =(C40-D40) -> -2.2737368e-12
A43: TOTAL | F43: =SUM(F36:F40) -> 13611.791
A52: COMPANY SUQIMSA
A53: (Leasing 3 ) Banco Aliado
D54: *este leasing se obtuvo en Nov del 2006
A55: Tasa = | C55: 0.082
A56: Years = | C56: 3
A58: FINACIAMIENTO
A59: Years | C59: Debt Balance at Beginning of Year | D59: Amortization del Loan | E59: Loan Interest Payment | F59: Total Pagado Amortization mas Inter AnnualIDAD | G59: Debt Balance at End of Year | H59: MONTHLYIDAD
F60: MAS
H63: =F64/12 -> 630.59202
A64: 2007 | C64: 19431 | D64: =(F64-E64) -> 5973.7623 | E64: =(C64*$C$55) -> 1593.342 | F64: =PMT($C$55,$C$56,-$C$64) -> 7567.1043 | G64: =(C64-D64) -> 13457.238
A65: 2008 | C65: =G64 -> 13457.238 | D65: =(F65-E65) -> 6463.6108 | E65: =(C65*$C$55) -> 1103.4935 | F65: =PMT($C$55,$C$56,-$C$64) -> 7567.1043 | G65: =(C65-D65) -> 6993.6269
A66: =A65+1 -> 2009 | C66: =G65 -> 6993.6269 | D66: =(F66-E66) -> 6993.6269 | E66: =(C66*$C$55) -> 573.47741 | F66: =PMT($C$55,$C$56,-$C$64) -> 7567.1043 | G66: =(C66-D66) -> -5.4569682e-12
A71: TOTAL | F71: =SUM(F64:F68) -> 22701.313
...

Sheet Balance Sheet
A2: SUQUIMSA
A3: BALANCE SHEET
A4: AL 31 DE DECEMBER DE 2007-2006
A5: (EN BALBOAS)
D6: HISTORICAL | F6: PROJECTED
A7: ACTIVOS | D7: 2006 | E7: 2007 | F7: =E7+1 -> 2008 | G7: =F7+1 -> 2009 | H7: =G7+1 -> 2010 | I7: =H7+1 -> 2011 | J7: =I7+1 -> 2012
A9: CORRIENTES
A10: Cash on Hand and at Bank | D10: 54025 | E10: 122370 | F10: =280000-143355-15004+6001 -> 127642 | G10: =305000-168892-1950 -> 134158 | H10: =320000+163000+914 -> 483914 | I10: =345000+699147 -> 1044147 | J10: =375000+1392202 -> 1767202
A11: Finished Goods Inventory | D11: 35580 | E11: 124852 | F11: ='P&L (Old)'!$G$9*F69 -> 174872.76 | G11: ='P&L (Old)'!$H$9*G69 -> 224274.2 | H11: ='P&L (Old)'!$I$9*H69 -> 282398.11 | I11: ='P&L (Old)'!$J$9*I69 -> 349986.28 | J11: ='P&L (Old)'!#REF!*J69 -> #REF!
A12: Raw Materials Inventory | D12: 49207 | E12: =199397-35000 -> 164397 | F12: ='P&L (Old)'!$G$9*F70 -> 234620.95 | G12: ='P&L (Old)'!$H$9*G70 -> 300901.22 | H12: ='P&L (Old)'!$I$9*H70 -> 380151.31 | I12: ='P&L (Old)'!$J$9*I70 -> 449982.36 | J12: ='P&L (Old)'!#REF!*J70 -> #REF!
A13: Accounts Receivable - Customers | D13: 175296.94 | E13: =333833-10757 -> 323076 | F13: ='P&L (Old)'!$G$9*F71 -> 437181.9 | G13: ='P&L (Old)'!$H$9*G71 -> 495272.19 | H13: ='P&L (Old)'!$I$9*H71 -> 575657.69 | I13: ='P&L (Old)'!$J$9*I71 -> 662474.03 | J13: ='P&L (Old)'!#REF!*J71 -> #REF!
A14: Total de Activos Corrientes | D14: =SUM(D10:D13) -> 314108.94 | E14: =SUM(E10:E13) -> 734695 | F14: =SUM(F10:F13) -> 974317.61 | G14: =SUM(G10:G13) -> 1154605.6 | H14: =SUM(H10:H13) -> 1722121.1 | I14: =SUM(I10:I13) -> 2506589.7 | J14: =SUM(J10:J13) -> #REF!
A16: PROPIEDAD, PLANTA Y EQUIPMENT
A17: Propiedad Galera | F17: 400000 | G17: =F17-(400000/15) -> 373333.33 | H17: =G17-(400000/15) -> 346666.67 | I17: =H17-(400000/15) -> 320000 | J17: =I17-(400000/15) -> 293333.33
A18: Equipment Industrial-Neto | D18: =57989.36-8006.5 -> 49982.86 | E18: 63818 | F18: =E18-'P&L (Old)'!G18 -> 45943 | G18: =F18-'P&L (Old)'!H18 -> 28068 | H18: =G18-'P&L (Old)'!I18 -> 10193 | I18: =H18-'P&L (Old)'!J18 -> -7682 | J18: =I18-'P&L (Old)'!#REF! -> #REF!
A19: Computer Equipment-Net | D19: 10325.42 | E19: 9026.06 | F19: =E19-1299 -> 7727.06 | G19: =F19-1299 -> 6428.06 | H19: =G19-1299 -> 5129.06 | I19: =H19-1299 -> 3830.06 | J19: =I19-1299 -> 2531.06
A20: Office Equipment-Net | D20: =6159.03-123.75 -> 6035.28 | E20: 12663 | F20: =E20-(12663/10) -> 11396.7 | G20: =F20-(12663/5) -> 8864.1 | H20: =G20-(12663/5) -> 6331.5 | I20: =H20-(12663/5) -> 3798.9 | J20: =I20-(12663/5) -> 1266.3
A21: Equipment Rodante-Neto | D21: 15332 | E21: 12988 | F21: =E21-2344 -> 10644 | G21: =F21-2344 -> 8300 | H21: =G21-2344 -> 5956 | I21: =H21-2344 -> 3612 | J21: =I21-2344 -> 1268
A22: Office Furniture-Net | D22: =9035.46-903.55 -> 8131.91 | E22: 7733.89 | F22: =E22-398 -> 7335.89 | G22: =F22-398 -> 6937.89 | H22: =G22-398 -> 6539.89 | I22: =H22-398 -> 6141.89 | J22: =I22-398 -> 5743.89
A23: Mejoras a la Propieda Arrendada | D23: 4613 | E23: 12717 | F23: =E23-618 -> 12099 | G23: =F23-618 -> 11481 | H23: =G23-618 -> 10863 | I23: =H23-618 -> 10245 | J23: =I23-618 -> 9627
A24: Furniture and Small Equipment-Net | D24: =3533.19-162.31 -> 3370.88 | E24: =3533.19-162.31 -> 3370.88 | F24: =E24-(3371/5) -> 2696.68 | G24: =F24-(3371/5) -> 2022.48 | H24: =G24-(3371/5) -> 1348.28 | I24: =H24-(3371/5) -> 674.08 | J24: =I24-(3371/5) -> -0.12
A25: Total Property, Plant, and Equipment | D25: =SUM(D18:D24) -> 97791.35 | E25: =SUM(E18:E24) -> 122316.83 | F25: =SUM(F17:F24) -> 497842.33 | G25: =SUM(G17:G24) -> 445434.86 | H25: =SUM(H17:H24) -> 393027.4 | I25: =SUM(I17:I24) -> 340619.93 | J25: =SUM(J17:J24) -> #REF!
A27: OTROS ACTIVOS
A28: Deposito de Garantia Local | D28: 2000 | E28: 2000 | F28: =E28 -> 2000 | G28: =F28 -> 2000 | H28: =G28 -> 2000 | I28: =H28 -> 2000 | J28: =I28 -> 2000
A29: Tax S/R Estimado | D29: 9333 | E29: 14333 | F29: ='P&L (Old)'!G40 -> 20401.822 | G29: ='P&L (Old)'!H40 -> 26165.323 | H29: ='P&L (Old)'!I40 -> 30412.105 | I29: ='P&L (Old)'!J40 -> 34998.628 | J29: ='P&L (Old)'!#REF! -> #REF!
A30: Total de Otros Activos | D30: =SUM(D28:D29) -> 11333 | E30: =SUM(E28:E29) -> 16333 | F30: =SUM(F28:F29) -> 22401.822 | G30: =SUM(G28:G29) -> 28165.323 | H30: =SUM(H28:H29) -> 32412.105 | I30: =SUM(I28:I29) -> 36998.628 | J30: =SUM(J28:J29) -> #REF!
A32: TOTAL DE ACTIVOS | D32: =SUM(D14+D25+D30) -> 423233.29 | E32: =SUM(E14+E25+E30) -> 873344.83 | F32: =SUM(F14+F25+F30) -> 1494561.8 | G32: =SUM(G14+G25+G30) -> 1628205.8 | H32: =SUM(H14+H25+H30) -> 2147560.6 | I32: =SUM(I14+I25+I30) -> 2884208.2 | J32: =SUM(J14+J25+J30) -> #REF!
A34: PASIVOS Y EQUITY DE LOS ACCIONISTAS
A36: CORRIENTES
A37: Cuenta por Pagar-Suppliers | D37: 31284 | E37: 44712.59 | F37: ='P&L (Old)'!G11*F73 -> 89955.161 | G37: ='P&L (Old)'!H11*G73 -> 109446.97 | H37: ='P&L (Old)'!I11*H73 -> 121842.24 | I37: ='P&L (Old)'!J11*I73 -> #REF! | J37: ='P&L (Old)'!#REF!*J73 -> #REF!
A38: Banco Aliado Leasing (Circulante) | D38: 14125 | E38: 14180 | F38: =E38 -> 14180 | G38: =F38 -> 14180 | H38: =G38 -> 14180 | I38: =H38 -> 14180 | J38: =I38 -> 14180
A39: Loan Finance Capital Devel (Circulante) | D39: 6661.58 | E39: 36418 | F39: =LOANS!F19+LOANS!#REF! -> #REF! | G39: =LOANS!#REF! -> #REF! | H39: 0 | I39: 0 | J39: 0
A40: Loan Galera (B. Aliado) | F40: =LOANS!#REF! -> #REF! | G40: =F40 -> #REF! | H40: =G40 -> #REF! | I40: =H40 -> #REF! | J40: =I40 -> #REF!
A41: Banco General Leasing (Circulante) | D41: 0 | E41: 11565 | F41: =LEASING!F135 -> 15428.804 | G41: =F41 -> 15428.804 | H41: =G41 -> 15428.804 | I41: =H41 -> 15428.804 | J41: =I41 -> 15428.804
A42: Retenciones por Pagar-C.S.S | D42: 1728.89 | E42: 1734.77 | F42: =E42 -> 1734.77 | G42: =F42 -> 1734.77 | H42: =G42 -> 1734.77 | I42: =H42 -> 1734.77 | J42: =I42 -> 1734.77
A43: ITBMS por pagar | D43: 554.92 | E43: 1619.08 | F43: =E43 -> 1619.08 | G43: =F43 -> 1619.08 | H43: =G43 -> 1619.08 | I43: =H43 -> 1619.08 | J43: =I43 -> 1619.08
A44: Tax S/R por pagar | D44: 9333 | E44: 14333 | F44: ='P&L (Old)'!G40 -> 20401.822 | G44: ='P&L (Old)'!H40 -> 26165.323 | H44: ='P&L (Old)'!I40 -> 30412.105 | I44: ='P&L (Old)'!J40 -> 34998.628 | J44: ='P&L (Old)'!#REF! -> #REF!
A45: Total de Pasivos Corrientes | D45: =SUM(D37:D44) -> 63687.39 | E45: =SUM(E37:E44) -> 124562.44 | F45: =SUM(F37:F44) -> #REF! | G45: =SUM(G37:G44) -> #REF! | H45: =SUM(H37:H44) -> #REF! | I45: =SUM(I37:I44) -> #REF! | J45: =SUM(J37:J44) -> #REF!
A47: LARGO PLAZO
A48: Loan Finance Capital Devel | D48: 53292.67 | E48: 72212 | F48: =LOANS!G19+LOANS!#REF! -> #REF! | G48: 0 | H48: 0 | I48: 0 | J48: 0
...

Sheet Cash Flow
A1: =Costs!A1:I1 -> Company Suquimsa | D1: <<Contenido
A2: Cash Flow
A3: =+#REF! -> #REF!
A5: Cuentas | C5: HISTORICAL | D5: PROJECTED
C6: 2007 | D6: 2008 | E6: =D6+1 -> 2009 | F6: =E6+1 -> 2010 | G6: =F6+1 -> 2011 | H6: =G6+1 -> 2012
B7: REVENUE
B9: SALES | C9: =Revenue!E23 -> 1415524 | D9: =Revenue!F23 -> 1457273 | E9: =Revenue!G23 -> 1868951.7 | F9: =Revenue!H23 -> 2172293.2 | G9: =Revenue!I23 -> 2499902 | H9: =Revenue!#REF! -> #REF!
B11: EXPENSES
B13: COST OF SALES | C13: ='P&L (Old)'!F11 -> 445602 | D13: ='P&L (Old)'!G11 -> 749626.34 | E13: ='P&L (Old)'!H11 -> 841899.78 | F13: ='P&L (Old)'!I11 -> 937247.98 | G13: ='P&L (Old)'!J11 -> #REF! | H13: ='P&L (Old)'!#REF! -> #REF!
B15: ADMINISTRATIVE AND GENERAL EXPENSES | C15: =SUM(C16:C20) -> #REF! | D15: =SUM(D16:D20) -> #REF! | E15: =SUM(E16:E20) -> #REF! | F15: =SUM(F16:F20) -> #REF! | G15: =SUM(G16:G20) -> #REF! | H15: =SUM(H16:H20) -> #REF!
B16: Personal | C16: ='P&L (Old)'!F16 -> 120000 | D16: ='P&L (Old)'!G16 -> 215841.6 | E16: ='P&L (Old)'!H16 -> 226633.68 | F16: ='P&L (Old)'!I16 -> 237965.36 | G16: ='P&L (Old)'!J16 -> 249863.63 | H16: ='P&L (Old)'!#REF! -> #REF!
B17: Sales commission | C17: ='P&L (Old)'!F17 -> 13238.173 | D17: ='P&L (Old)'!G17 -> 18944.549 | E17: ='P&L (Old)'!H17 -> 24296.372 | F17: ='P&L (Old)'!I17 -> 28239.811 | G17: ='P&L (Old)'!J17 -> 32498.726 | H17: ='P&L (Old)'!#REF! -> #REF!
B18: Common administrative expenses | C18: ='P&L (Old)'!F19 -> #REF! | D18: ='P&L (Old)'!G19 -> #REF! | E18: ='P&L (Old)'!H19 -> #REF! | F18: ='P&L (Old)'!I19 -> #REF! | G18: ='P&L (Old)'!J19 -> #REF! | H18: ='P&L (Old)'!#REF! -> #REF!
B19: Marketing and advertising expenses | C19: ='P&L (Old)'!F20 -> #REF! | D19: ='P&L (Old)'!G20 -> 50000 | E19: ='P&L (Old)'!H20 -> 37500 | F19: ='P&L (Old)'!I20 -> 28125 | G19: ='P&L (Old)'!J20 -> 28125 | H19: ='P&L (Old)'!#REF! -> #REF!
B20: Other expenses | C20: ='P&L (Old)'!F21 -> 678117.82 | D20: ='P&L (Old)'!G21 -> 745929.6 | E20: ='P&L (Old)'!H21 -> 820522.56 | F20: ='P&L (Old)'!I21 -> 902574.82 | G20: ='P&L (Old)'!J21 -> 992832.3 | H20: ='P&L (Old)'!#REF! -> #REF!
B22: FINANCIAL EXPENSES | C22: =SUM(C23:C31) -> #REF! | D22: =SUM(D23:D31) -> #REF! | E22: =SUM(E23:E31) -> #REF! | F22: =SUM(F23:F31) -> #REF! | G22: =SUM(G23:G31) -> #REF! | H22: =SUM(H23:H31) -> #REF!
B23: Loan Financing 1 | C23: =LOANS!F17 -> 101915.9 | D23: =LOANS!F18 -> 101915.9 | E23: =LOANS!F19 -> 101915.9 | F23: =LOANS!F20 -> 101915.9 | G23: 0 | H23: 0
B24: Loan Financing 2 | C24: =LOANS!#REF! -> #REF! | D24: =LOANS!#REF! -> #REF! | E24: =LOANS!#REF! -> #REF! | F24: =LOANS!#REF! -> #REF! | G24: 0 | H24: 0
B25: Leasing 1 | C25: =LEASING!F15 -> 5949.3298 | D25: =LEASING!F16 -> 5949.3298 | E25: =LEASING!F17 -> 5949.3298 | F25: =LEASING!F18 -> 0 | G25: 0 | H25: 0
B26: Leasing 2 | C26: =LEASING!F37 -> 3402.9477 | D26: =LEASING!F38 -> 3402.9477 | E26: =LEASING!F39 -> 3402.9477 | F26: =LEASING!F40 -> 3402.9477 | G26: 0 | H26: 0
B27: Leasing 3 | C27: =LEASING!F64 -> 7567.1043 | D27: =LEASING!F65 -> 7567.1043 | E27: =LEASING!F66 -> 7567.1043 | F27: =LEASING!F67 -> 0 | G27: 0 | H27: 0
B28: Leasing 4 | C28: =LEASING!F86 -> 3902.3855 | D28: =LEASING!F87 -> 3902.3855 | E28: =LEASING!F88 -> 3902.3855 | F28: =LEASING!F89 -> 0 | G28: 0 | H28: 0
B29: Leasing 5 | D29: =LEASING!F112 -> 14127.804 | E29: =LEASING!F113 -> 14127.804 | F29: =LEASING!F114 -> 14127.804 | G29: =LEASING!F115 -> 14127.804 | H29: 0
B30: Leasing 6 | C30: =LEASING!F134 -> 15428.804 | D30: =LEASING!F135 -> 15428.804 | E30: =LEASING!F136 -> 15428.804 | F30: =LEASING!F137 -> 15428.804 | G30: =LEASING!F138 -> 15428.804 | H30: =LEASING!F139 -> 15428.804
B31: Mortgage loan | D31: =LOANS!#REF!*6 -> #REF! | E31: =LOANS!#REF!*12 -> #REF! | F31: =E31 -> #REF! | G31: =F31 -> #REF! | H31: =G31 -> #REF!
B33: TAXES (CAIR) | C33: ='P&L (Old)'!F40 -> 14256.494 | D33: ='P&L (Old)'!G40 -> 20401.822 | E33: ='P&L (Old)'!H40 -> 26165.323 | F33: ='P&L (Old)'!I40 -> 30412.105 | G33: ='P&L (Old)'!J40 -> 34998.628 | H33: ='P&L (Old)'!#REF! -> #REF!
B34: CASH | C34: =C9-C13-C15-C22-C33 -> #REF! | D34: =D9-D13-D15-D22-D33 -> #REF! | E34: =E9-E13-E15-E22-E33 -> #REF! | F34: =F9-F13-F15-F22-F33 -> #REF! | G34: =G9-G13-G15-G22-G33 -> #REF! | H34: =H9-H13-H15-H22-H33 -> #REF!

Sheet 7.-Balance Sheet
B1: <<Contenido | D1: ='P&L (Old)'!A1 -> Company Suquimsa
D2: ='P&L (Old)'!F1 -> 0
D3: BALANCE SHEET
D4: =+Revenue!C3 -> (Values in Dollars)
A6: Cuentas | C6: HISTORICAL | F6: PROJECTED
C7: 2005 | D7: 2006 | E7: 2007 | F7: 2008 | G7: =F7+1 -> 2009 | H7: =G7+1 -> 2010 | I7: =H7+1 -> 2011 | J7: =I7+1 -> 2012
A9: ASSET | G9: JUAN, TO COMPLETE THIS BALANCE SHEET
G10: NECESITAMOS DISCUTIR LAS PROXIMAS INVESTMENTES
B11: Activos Corrientes | C11: =SUM(C12:C14) -> 95615 | D11: =SUM(D12:D14) -> 250451.2 | E11: =SUM(E12:E14) -> 435878.3 | F11: =SUM(F12:F14) -> 715228.9 | G11: EN ACTIVOS Y Machinery…
B12: Cash or bank | C12: 7664 | D12: 1884.26 | E12: 0 | F12: 0
B13: Accounts Receivable | C13: 64492 | D13: 175296.94 | E13: =+'P&L (Old)'!F9*J13 -> 305496.3 | F13: =+'P&L (Old)'!G9*K13 -> 437181.9 | H13: =C13/'P&L (Old)'!D9 -> #REF! | I13: =D13/'P&L (Old)'!E9 -> 0.26315567 | J13: 0.3 | K13: 0.3
B14: Inventory | C14: =24569-1110 -> 23459 | D14: 73270 | E14: =116357+14025 -> 130382 | F14: =271086+6961 -> 278047 | H14: =C14/'P&L (Old)'!D9 -> #REF! | I14: =D14/'P&L (Old)'!E9 -> 0.10999288 | J14: =E14/'P&L (Old)'!F9 -> 0.12803625 | K14: =F14/'P&L (Old)'!G9 -> 0.19079953
E15: 0 | F15: 0
B16: Fixed Assets (Eq, etc.) | C16: =SUM(C17:C25) -> 46123 | D16: =SUM(D17:D25) -> 82459.35 | E16: =SUM(E17:E25) -> 83823.93 | F16: =SUM(F17:F25) -> 83823.93
B17: Eqipo Industrial | C17: 17460 | D17: 49982.86 | E17: 49982.86 | F17: 49982.86
B18: Depreciation EI
B19: Eqipo de Computadora | C19: 11690 | D19: 10325.42 | E19: 11690 | F19: 11690
B20: Depreciation EC
B21: Eqipo de Oficina | C21: 2351 | D21: 6035.28 | E21: 6035.28 | F21: 6035.28
B22: Depreciation EO
B23: Office Furniture | C23: 8108 | D23: 8131.91 | E23: 8131.91 | F23: 8131.91
B24: Furniture and Small Equipment | C24: 3084 | D24: 3370.88 | E24: 3370.88 | F24: 3370.88
B25: Mejoras al local arrendado | C25: 3430 | D25: 4613 | E25: 4613 | F25: 4613
B27: Otros | D27: =SUM(D28:D29) -> 11333 | E27: =SUM(E28:E29) -> 2000 | F27: =SUM(F28:F29) -> 2000
B28: Depositos de Garantia | C28: 2000 | D28: 2000 | E28: 2000 | F28: 2000
B29: Tax S/R Estimado | D29: 9333
B33: TOTAL DE ACTIVOS | C33: =+C11+C16+C28 -> 143738 | D33: =+D11+D16+D27 -> 344243.55 | E33: =+E11+E16+E27 -> 521702.23 | F33: =+F11+F16+F27 -> 801052.83
A35: LIABILITY
B37: Pasivos Corrientes | C37: =SUM(C38:C45) -> 44407 | D37: =SUM(D38:D44) -> 56545.89 | E37: =SUM(E38:E40) -> #REF! | F37: =SUM(F38:F40) -> #REF! | H37: =C38/'P&L (Old)'!D11 -> #DIV/0! | I37: =D38/'P&L (Old)'!E11 -> 0.14005861 | J37: =E38/'P&L (Old)'!F11 -> 0.15 | K37: =F38/'P&L (Old)'!G11 -> 0.15
B38: Cuenta por Pagar-Suppliers | C38: 30583 | D38: 37278 | E38: =+'P&L (Old)'!F11*0.15 -> 66840.3 | F38: =+'P&L (Old)'!G11*0.15 -> 112443.95
B39: Loan Banco Aliado Leasing | D39: =494.75*2 -> 989.5 | E39: =LEASING!F15+LEASING!F37 -> 9352.2775 | F39: =LEASING!F16+LEASING!F38 -> 9352.2775
B40: Loan Finance Capital Devel (2005 no es Financia) | C40: 12997 | D40: 6661.58 | E40: =LOANS!F18+LOANS!#REF! -> #REF! | F40: =E40 -> #REF!
B41: Retenciones por Pagar-C.S.S | C41: 827 | D41: 1728.89 | E41: 0 | F41: 0
B42: ITBMS por pagar | D42: 554.92 | E42: 0 | F42: 0
B43: Tax S/R por pagar | D43: 9333 | E43: 0 | F43: 0
B46: Pasivos de largo plazo | C46: =C47 -> 0 | D46: =D47+D48 -> 683140 | E46: =E47+E48 -> #REF! | F46: =F47+F48 -> #REF!
B47: Loan Finance Capital Devel | C47: 0 | D47: =LOANS!G17+18310 -> 668797.5 | E47: =+LOANS!G18+LOANS!#REF! -> #REF! | F47: =+LOANS!G19+LOANS!#REF! -> #REF!
B48: Loan Banco Aliado Leasing | D48: =15332-D39 -> 14342.5 | E48: =LEASING!G15+LEASING!G37 -> 19347.404 | F48: =LEASING!G16+LEASING!G38 -> 11560.396
B49: TOTAL DE PASIVOS | C49: =C46+C37 -> 44407 | D49: =D46+D37 -> 739685.89 | E49: =E46+E37 -> #REF! | F49: =F46+F37 -> #REF!
A51: CAPITAL
...

Sheet Ratios
A1: =LOANS!A1:H1 -> Company Suquimsa
A2: <<Contenido
A3: Razones Financial
A4: Rentbilidad | C4: 2006 | D4: 2007 | E4: 2008 | F4: =E4+1 -> 2009 | G4: =F4+1 -> 2010 | H4: =G4+1 -> 2011 | I4: =H4+1 -> 2012
